<?xml version='1.0'?>

<!-- This is a URDF description file of a mobile robot, written by Muhammad Asem, m7mad3asem@gmail.com
It models: 1-Chassis with Caster Wheel 2-Left wheel 3-right Wheel  4-Kinect /-->


<robot name="myrobot" xmlns:xacro="http://www.ros.org/wiki/xacro">


<!-- +++++++++++++++++++++++Robot Definition+++++++++++++++++++++++++ /-->



<!--Chassis & Caster Link /-->

 <link name='chassis'>

   <visual name='chassis_visual'>

      <origin xyz="0 0 0" rpy=" 0 0 0"/>

      <geometry>
        <box size=".6 .3 .1"/>
      </geometry>

    </visual>    
    
  
   <inertial>

      <mass value="10.0"/>
      <origin xyz="0 0 0" rpy=" 0 0 0"/>
      <inertia
          ixx="0.5" ixy="0" ixz="0"
          iyy="1.0" iyz="0"
          izz="0.1"
      />

   </inertial>
  

   <collision name='collision'>
      <geometry>
        <box size=".6 .3 .1"/>
      </geometry>
   </collision>



 <collision name='caster_collision'>
    <origin xyz="-0.2 0 -0.05" rpy=" 0 0 0"/>

    <geometry>
        <sphere radius="0.05"/>
    </geometry>

    <surface>

        <friction>
          <ode>
            <mu>0</mu>
            <mu2>0</mu2>
            <slip1>1.0</slip1>
            <slip2>1.0</slip2>
          </ode>
        </friction>

     </surface>

 </collision>

<visual name='caster_visual'>

     <origin xyz="-0.2 0 -0.05" rpy=" 0 0 0"/>

     <geometry>
      <sphere radius="0.05"/>
     </geometry>

</visual>

</link>


<!-- ++++++++++++++++Left wheel+++++++++++++++++++++++++++++++ /-->


<!--left wheel Joint /-->

  <joint type="continuous" name="left_wheel_hinge">
    <origin xyz="0.1 0.175 0" rpy="0 0 0"/>
    <child link="left_wheel"/>
    <parent link="chassis"/>
    <axis xyz="0 1 0" rpy="0 0 0"/>
    <limit effort="100" velocity="100"/>
    <joint_properties damping="0.0" friction="0.0"/>
  </joint>



<!--left wheel Link /-->

 <link name="left_wheel">

    <visual name="left_wheel_visual">
      <origin xyz="0 0 0" rpy="0 1.5707 1.5707"/>
      <geometry>
        <cylinder radius="0.1" length="0.05"/>
      </geometry>
    </visual>


    <collision name="collision">
      <origin xyz="0 0 0" rpy="0 1.5707 1.5707"/>
      <geometry>
        <cylinder radius="0.1" length="0.05"/>
      </geometry>
    </collision>

    

    <inertial>
      <origin xyz="0 0 0" rpy="0 1.5707 1.5707"/>
      <mass value="5"/>
      <cylinder_inertia m="5" r="0.1" h="0.05"/>
      <inertia
        ixx="1.0" ixy="0.0" ixz="0.0"
        iyy="1.0" iyz="0.0"
        izz="1.0"/>
    </inertial>

 </link>

<!-- +++++++++++++++++++ Right Wheel +++++++++++++++++++++++++++++++++ /-->

<!--Right wheel joint/-->
  <joint type="continuous" name="right_wheel_hinge">

    <origin xyz="0.1 -0.175 0" rpy="0 0 0"/>
    
    <child link="right_wheel"/>
    <parent link="chassis"/>

    <axis xyz="0 1 0" rpy="0 0 0"/>

    <limit effort="100" velocity="100"/>

    <joint_properties damping="0.0" friction="0.0"/>

  </joint>

<!--Right Wheel link /-->

  <link name="right_wheel">

    <visual name="right_wheel_visual">

      <origin xyz="0 0 0" rpy="0 1.5707 1.5707"/>

      <geometry>
        <cylinder radius="0.1" length="0.05"/>
      </geometry>

    </visual>

    
    <collision name="collision">

      <origin xyz="0 0 0" rpy="0 1.5707 1.5707"/>

      <geometry>
        <cylinder radius="0.1" length="0.05"/>
      </geometry>

    </collision>


    <inertial>

      <origin xyz="0 0 0" rpy="0 1.5707 1.5707"/>
      <mass value="5"/>
      <cylinder_inertia m="5" r="0.1" h="0.05"/>

      <inertia
        ixx="1.0" ixy="0.0" ixz="0.0"
        iyy="1.0" iyz="0.0"
        izz="1.0"/>
      </inertial>

  </link>


<!-- ++++++++++++++++++  rplidar  +++++++++++++++++++++++++++++ /-->
<!--rplidar joint /-->

<joint name="rplidar_joint" type="fixed">

    <origin xyz=".15 0 .1" rpy="0 0 0"/>

    <parent link="chassis"/>
    <child link="rplidar_link"/>

</joint>


<!--rplidar  Link /-->

<link name="rplidar_link">
	<visual>
            <geometry>
                <cylinder radius="0.05" length="0.07"/>
            </geometry>
            <material name="red"/>
        </visual>
        <collision>
            <geometry>
                <cylinder radius="0.05" length="0.07"/>
            </geometry>
        </collision>
        <xacro:inertial_cylinder mass="0.1" length="0.07" radius="0.05">
            <origin xyz="0 0 0" rpy="0 0 0"/>
        </xacro:inertial_cylinder>
</link>

	<!--  ++++++++++++++++++Gazebo Plugins+++++++++++++++++++          /-->
<gazebo>
    <plugin name="differential_drive_controller" filename="libgazebo_ros_diff_drive.so">
      <legacyMode>false</legacyMode>
      <alwaysOn>true</alwaysOn>

      <updateRate>20</updateRate>

      <leftJoint>left_wheel_hinge</leftJoint>
      <rightJoint>right_wheel_hinge</rightJoint>
      
      <publishWheelJointState>true</publishWheelJointState>

      <wheelSeparation>0.4</wheelSeparation>
      <wheelDiameter>0.1</wheelDiameter>

      <Torque>20</Torque>

      <commandTopic>cmd_vel</commandTopic> <!--   listening to the topic "cmd_vel"   : to move the robot      /-->
      <odometryTopic>odom</odometryTopic>
      <odometryFrame>odom</odometryFrame>
      <robotBaseFrame>chassis</robotBaseFrame>
      
    <!--  <publish_odom>true</publish_odom> 
      <publishOdomTF>true</publishOdomTF>
      <publishWheelTF>true</publishWheelTF>
/-->
    
      </plugin>
      
      
 </gazebo>
<!--  +++++++++++++Chassis Orange color++++++++++++++++          /-->

  <gazebo reference="chassis">
    <material>Gazebo/Orange</material>
  </gazebo>

<!--  ++++++++++++++++Left wheel Blue Color+++++++++++++++++++          /-->
  <gazebo reference="left_wheel">
    <material>Gazebo/Blue</material>
  </gazebo>
<!--  +++++++++++++++Right wheel Blue Color+++++++++++++++++          /-->
  <gazebo reference="right_wheel">
    <material>Gazebo/Blue</material>
  </gazebo>

<!--  ++++++++++++++++++rplidar Plugin+++++++++++++++++++          /-->
<gazebo reference="rplidar_link">
	
	
	<material>Gazebo/Red</material>

        <sensor name="laser" type="ray">
            <pose> 0 0 0 0 0 0 </pose>
            <visualize>true</visualize>
            <update_rate>5.5</update_rate>
            <ray>
                <scan>
                    <horizontal>
                        <samples>2048</samples>
                        <min_angle>-3.14</min_angle>
                        <max_angle>3.14</max_angle>
                    </horizontal>
                </scan>
                <range>
                    <min>0.3</min>
                    <max>12</max>
                </range>
            </ray>
            <plugin name="laser_controller" filename="libgazebo_ros_laser.so">
                
                <output_type>sensor_msgs/LaserScan</output_type>
                <topicName>/scan</topicName>
                <frameName>rplidar_link</frameName>
            </plugin>
        </sensor>
    
</gazebo>
</robot>
